Workbook
Name \s: #REF!
Name ___DAT6: #REF!
Name __DAT1: #REF!
Name __DAT10: #REF!
Name __DAT11: #REF!
Name __DAT12: #REF!
Name __DAT13: #REF!
Name __DAT14: #REF!
Name __DAT15: #REF!
Name __DAT16: #REF!
Name __DAT17: #REF!
Name __DAT18: #REF!
Name __DAT19: #REF!
Name __DAT2: #REF!
Name __DAT20: #REF!
Name __DAT21: #REF!
Name __DAT22: #REF!
Name __DAT23: #REF!
Name __DAT24: #REF!
Name __DAT25: #REF!
Name __DAT26: #REF!
Name __DAT27: #REF!
Name __DAT28: #REF!
Name __DAT29: #REF!
Name __DAT3: #REF!
Name __DAT30: #REF!
Name __DAT31: #REF!
Name __DAT32: #REF!
Name __DAT33: #REF!
Name __DAT34: #REF!
Name __DAT35: #REF!
Name __DAT36: #REF!
Name __DAT37: #REF!
Name __DAT38: #REF!
Name __DAT39: #REF!
Name __DAT4: #REF!
Name __DAT40: #REF!
Name __DAT41: #REF!
Name __DAT42: #REF!
Name __DAT43: #REF!
Name __DAT44: #REF!
Name __DAT45: #REF!
Name __DAT46: #REF!
Name __DAT47: #REF!
Name __DAT48: #REF!
Name __DAT49: #REF!
Name __DAT5: #REF!
Name __DAT50: #REF!
Name __DAT51: #REF!
Name __DAT52: #REF!
Name __DAT53: #REF!
Name __DAT54: #REF!
Name __DAT55: #REF!
Name __DAT56: #REF!
Name __DAT57: #REF!
Name __DAT58: #REF!
Name __DAT59: #REF!
Name __DAT6: #REF!
Name __DAT60: #REF!
Name __DAT7: #REF!

Sheet Scope 1 Consolidated
A1: SCOPE 1 CONSOLIDATED GHG EMISSIONS (tCO₂e)
A3: Emission Source | B3: Category | C3: FY 2024-25 | D3: FY 2023-24 | E3: FY 2022-23 | F3: FY 2021-22 | G3: FY 2020-21
C4: (tCO₂e) | D4: (tCO₂e) | E4: (tCO₂e) | F4: (tCO₂e) | G4: (tCO₂e)
A5: Stationary Combustion | B5: Scope 1 | C5: ='Scope 1 Stationary Combustion'!#REF! -> #REF! | D5: ='Scope 1 Stationary Combustion'!#REF! -> #REF! | E5: N/A | F5: N/A | G5: N/A
A6: Mobile Combustion - HSD | B6: Scope 1 | C6: ='Scope 1 Mobile Combustion'!#REF! -> #REF! | D6: ='Scope 1 Mobile Combustion'!#REF! -> #REF! | E6: ='Scope 1 Mobile Combustion'!#REF! -> #REF! | F6: ='Scope 1 Mobile Combustion'!#REF! -> #REF! | G6: ='Scope 1 Mobile Combustion'!#REF! -> #REF!
A7: Mobile Combustion - Petrol | B7: Scope 1 | C7: ='Scope 1 Mobile Combustion'!#REF! -> #REF! | D7: ='Scope 1 Mobile Combustion'!#REF! -> #REF! | E7: ='Scope 1 Mobile Combustion'!#REF! -> #REF! | F7: ='Scope 1 Mobile Combustion'!#REF! -> #REF! | G7: ='Scope 1 Mobile Combustion'!#REF! -> #REF!
A8: Mobile Combustion Subtotal | B8: Scope 1 | C8: =C6+C7 -> #REF! | D8: =D6+D7 -> #REF! | E8: =E6+E7 -> #REF! | F8: =F6+F7 -> #REF! | G8: =G6+G7 -> #REF!
A9: Fugitive Emissions - Refrigerants | B9: Scope 1 | C9: ='Scope 1 Fugitive Emissions'!#REF! -> #REF! | D9: ='Scope 1 Fugitive Emissions'!#REF! -> #REF! | E9: ='Scope 1 Fugitive Emissions'!K56 -> 2471.931 | F9: ='Scope 1 Fugitive Emissions'!K18 -> 2741.778 | G9: ='Scope 1 Fugitive Emissions'!K37 -> 2923.3286
A10: Fugitive Emissions - CO₂ Extinguishers | B10: Scope 1 | C10: ='Scope 1 Fugitive Emissions'!#REF!-'Scope 1 Fugitive Emissions'!#REF! -> #REF! | D10: ='Scope 1 Fugitive Emissions'!#REF!-'Scope 1 Fugitive Emissions'!#REF! -> #REF! | E10: =('Scope 1 Fugitive Emissions'!M56*2+'Scope 1 Fugitive Emissions'!N56*4.5+'Scope 1 Fugitive Emissions'!O56*9+'Scope 1 Fugitive Emissions'!P56*22.5+'Scope 1 Fugitive Emissions'!Q56*6+'Scope 1 Fugitive Emissions'!R56*3+'Scope 1 Fugitive Emissions'!S56*1+'Scope 1 Fugitive Emissions'!T56*2.5)/1000 -> 1.51 | F10: =SUM('Scope 1 Fugitive Emissions'!M19:T19) -> 0.363 | G10: N/A
A11: Fugitive Emissions Subtotal | B11: Scope 1 | C11: =C9+C10 -> #REF! | D11: =D9+D10 -> #REF! | E11: =E9+E10 -> 2473.441 | F11: =F9+F10 -> 2742.141 | G11: =G9 -> 2923.3286
A13: TOTAL SCOPE 1 EMISSIONS | C13: =C5+C8+C11 -> #REF! | D13: =D5+D8+D11 -> #REF! | E13: =E8+E11 -> #REF! | F13: =F8+F11 -> #REF! | G13: =G8+G11 -> #REF!
A15: Biogenic Emissions (reported separately) | B15: Biogenic | C15: ='Scope 1 Stationary Combustion'!#REF! -> #REF! | D15: ='Scope 1 Stationary Combustion'!#REF! -> #REF! | E15: N/A | F15: N/A | G15: N/A
A17: Notes: | B17: IPCC 2006 Guidelines, AR6 GWPs (CH₄=27, N₂O=273). Refrigerant GWPs updated to AR6. N/A = Not calculated for that year.

Sheet Scope 1 Stationary Combustion
B2: Stationary combustion | N2: Stationary combustion | U2: BIOGENIC
C3: FY2023-24 | D3: FY2023-24 | E3: FY2023-24 | F3: FY2023-24 | G3: FY2023-24 | H3: FY2023-24 | I3: FY2023-24 | J3: FY2023-24 | O3: FY2024-25 | P3: FY2024-25 | Q3: FY2024-25 | R3: FY2024-25 | S3: FY2024-25 | T3: FY2024-25 | U3: FY2024-25 | V3: FY2024-25 | W3: FY2024-25
C4: HSD (KL) | D4: Furnance Oil (KL) | E4: LDO (KL) | F4: Natural Gas (SCM) | G4: LPG (Kg) | H4: LSHS (KL) | I4: Biofuel (KL) | J4: Biodiesel (KL) | O4: HSD (KL) | P4: Furnance Oil (KL) | Q4: LDO (KL) | R4: Natural Gas (SCM) | S4: LPG (Kg) | T4: LSHS (KL) | U4: Biofuel (KL) | V4: Biodiesel (KL) | W4: Briquettes (Kg)
B6: Baddi | C6: 150.353 | D6: 0 | E6: 0 | F6: 0 | G6: 59158 | H6: 578.78 | I6: 0 | J6: 0 | N6: Baddi | O6: 222.938 | P6: 0 | Q6: 0 | R6: 0 | S6: 16944 | T6: 477.436 | U6: 0 | V6: 0 | W6: 699725
B7: Goa | C7: 319.012 | D7: 0 | E7: 0 | F7: 6070.85 | G7: 0 | H7: 1140.77 | I7: 0 | J7: 0 | N7: Goa | O7: 380.171 | P7: 0 | Q7: 0 | R7: 1387517.3 | S7: 0 | T7: 120.457 | U7: 0 | V7: 0 | W7: 0
B8: Indore | C8: 30.708 | D8: 934.006 | E8: 0 | F8: 0 | G8: 0 | H8: 0 | I8: 0 | J8: 0 | N8: Indore | O8: 29.88 | P8: 1000.49 | Q8: 0 | R8: 0 | S8: 0 | T8: 0 | U8: 0 | V8: 0 | W8: 0
B9: Nashik | C9: 7.18 | D9: 0 | E9: 0 | F9: 0 | G9: 0 | H9: 0 | I9: 0 | J9: 86.758 | N9: Nashik | O9: 33.8 | P9: 0 | Q9: 0 | R9: 0 | S9: 0 | T9: 0 | U9: 0 | V9: 99.296 | W9: 0
B10: Nalagarh | C10: 23.005 | D10: 0 | E10: 0 | F10: 0 | G10: 57466.229 | H10: 0 | I10: 0 | J10: 0 | N10: Nalagarh | O10: 24.554 | P10: 0 | Q10: 0 | R10: 0 | S10: 35138.77 | T10: 0 | U10: 0 | V10: 0 | W10: 0
B11: Sikkim | C11: 57.702 | D11: 0 | E11: 201.756 | F11: 0 | G11: 0 | H11: 0 | I11: 0 | J11: 0 | N11: Sikkim | O11: 65.12 | P11: 0 | Q11: 191.336 | R11: 0 | S11: 0 | T11: 0 | U11: 0 | V11: 0 | W11: 0
B12: Dindori | C12: 2.2 | D12: 0 | E12: 0 | N12: Dindori | O12: 7.995 | P12: 0 | Q12: 0 | R12: 0 | S12: 0 | T12: 0 | U12: 0 | V12: 0 | W12: 0
B13: Aurangabad | C13: 27.07 | D13: 0 | E13: 0 | F13: 0 | G13: 0 | H13: 0 | I13: 290.27 | J13: 0 | N13: Aurangabad | O13: 81.068 | P13: 0 | Q13: 0 | R13: 0 | S13: 0 | T13: 0 | U13: 587.76 | V13: 0 | W13: 0
B14: Mahape | C14: 6.16462 | D14: 0 | E14: 0 | F14: 0 | G14: 0 | H14: 0 | I14: 0 | J14: 0 | N14: Mahape | O14: 3.3028 | P14: 0 | Q14: 0 | R14: 0 | S14: 0 | T14: 0 | U14: 0 | V14: 0 | W14: 0
B15: Sinnar | C15: 3.904 | D15: 0 | E15: 0 | F15: 0 | G15: 0 | H15: 0 | I15: 0 | J15: 0 | N15: Sinnar | O15: 5.106 | P15: 0 | Q15: 0 | R15: 0 | S15: 0 | T15: 0 | U15: 0 | V15: 0 | W15: 0
B16: Taloja | C16: 30.287 | D16: 0 | E16: 0 | F16: 0 | G16: 0 | H16: 0 | I16: 0 | J16: 0 | N16: Taloja | O16: 19.499 | P16: 0 | Q16: 0 | R16: 0 | S16: 0 | T16: 0 | U16: 0 | V16: 0 | W16: 0
B17: Sanpada | C17: 0 | D17: 0 | E17: 0 | F17: 0 | G17: 0 | H17: 0 | I17: 0 | J17: 0 | N17: Sanpada | O17: 0 | P17: 0 | Q17: 0 | R17: 0 | S17: 0 | T17: 0 | U17: 0 | V17: 0 | W17: 0
B18: Total | C18: =SUM(C6:C17) -> 657.58562 | D18: =SUM(D6:D17) -> 934.006 | E18: =SUM(E6:E17) -> 201.756 | F18: =SUM(F6:F17) -> 6070.85 | G18: =SUM(G6:G17) -> 116624.23 | H18: =SUM(H6:H17) -> 1719.55 | I18: =SUM(I6:I17) -> 290.27 | J18: =SUM(J6:J17) -> 86.758 | N18: Total | O18: =SUM(O6:O17) -> 873.4338 | P18: =SUM(P6:P17) -> 1000.49 | Q18: =SUM(Q6:Q17) -> 191.336 | R18: =SUM(R6:R17) -> 1387517.3 | S18: =SUM(S6:S17) -> 52082.77 | T18: =SUM(T6:T17) -> 597.893 | U18: =SUM(U6:U17) -> 587.76 | V18: =SUM(V6:V17) -> 99.296 | W18: =SUM(W6:W17) -> 699725

Sheet Scope 1 Mobile Combustion
B1: Mobile combustion
C2: 2024-25 | E2: 2023-24 | G2: 2022-23 | I2: 2021-22 | K2: 2020-21
C3: HSD (KL) | D3: Petrol | E3: HSD (KL) | F3: Petrol | G3: HSD (KL) | H3: Petrol | I3: HSD (KL) | J3: Petrol | K3: HSD (KL) | L3: Petrol
G4: Vehicle | H4: Vehicle | I4: Vehicle | J4: Vehicle | K4: Vehicle | L4: Vehicle
A5: Formulation | B5: Baddi | C5: 0 | D5: 0 | E5: 0 | F5: 0 | G5: 0 | H5: 0 | I5: 0 | J5: 0
A6: Formulation | B6: Goa | C6: 0.948 | D6: 0.10651 | E6: 0.80676 | F6: 0.06156 | G6: 1.158 | H6: 0.118 | I6: 0.442 | J6: 0.275 | K6: 0.19 | L6: 0.256
A7: Formulation | B7: Indore | C7: 0 | D7: 0 | E7: 0 | F7: 0 | G7: 0 | H7: 0 | I7: 0 | J7: 0
A8: Formulation | B8: Nashik | C8: 0 | D8: 0.29656 | E8: 0 | F8: 0.33385 | G8: 0 | H8: 0.81853 | I8: 0 | J8: 0.2629 | L8: 0.3952
A9: Formulation | B9: Nalagarh | C9: 0 | D9: 0.045 | E9: 0 | F9: 0.054 | H9: 0.039 | I9: 0 | J9: 0.0422 | L9: 0.0622
A10: Formulation | B10: Sikkim | C10: 0 | D10: 0.09647 | E10: 0 | F10: 0.09 | H10: 0.11699 | I10: 0 | J10: 0.33902 | L10: 0.812
A12: Formulation | B12: Aurangabad | C12: 2.192 | D12: 0 | E12: 1.919 | F12: 0 | G12: 1.420298 | H12: 0 | I12: 1.50022 | J12: 0 | K12: 1.6738
B13: Dindori | C13: 0 | D13: 0 | E13: 0 | F13: 0
A16: R&D | B16: Mahape | C16: 0 | D16: 0.958 | E16: 0 | F16: 1.197 | G16: 0 | H16: 1.3274 | I16: 0 | J16: 2.663 | L16: 2.879
A17: R&D | B17: Sinnar | D17: 1.159 | E17: 0 | F17: 0.928 | G17: 0 | H17: 1.183 | I17: 0 | J17: 0.96635 | L17: 0.67
A18: R&D | B18: Taloja | C18: 0 | D18: 2.58208 | E18: 0 | F18: 4.60889 | G18: 0 | H18: 4.19064 | I18: 0 | J18: 4.959 | L18: 5.947
A19: R&D | B19: Sanpada | C19: 0 | D19: 0 | E19: 0 | F19: 0 | I19: 0 | J19: 2.721 | L19: 5.031
B20: Corporate | C20: 0 | D20: 5.313 | E20: 0 | F20: 5.313 | G20: 0 | H20: 0 | I20: 0 | J20: 9.682 | L20: 13.707
B21: Total | C21: =SUM(C5:C20) -> 3.14 | D21: =SUM(D5:D20) -> 10.55662 | E21: =SUM(E5:E20) -> 2.72576 | F21: =SUM(F5:F20) -> 12.5863 | G21: =SUM(G5:G20) -> 2.578298 | H21: =SUM(H5:H20) -> 7.79356 | I21: =SUM(I5:I20) -> 1.94222 | J21: =SUM(J5:J20) -> 21.91047 | ... L21: =SUM(L5:L20) -> 29.7594

Sheet Scope 1 Fugitive Emissions
A1: Due to refrigerant & CO2 type extinguishers refilled
A2: FY2021-22 | L2: CO2 Type fire extinguisher refilled in nos
A3: Plant | B3: R22 (kg) refilled | C3: R-134a (kg) refilled | D3: R-407c (kg) refilled | E3: R-404a (kg) refilled | F3: R-410a (kg) refilled | G3: R-407a (kg) refilled | H3: R123 (kg) refilled | I3: R32 (kg) refilled | L3: Plant | M3: 2 Kg (nos) | N3: 4.5 Kg (nos) | O3: 9 Kg (nos) | P3: 22.5 Kg (nos) | Q3: 6 Kg (nos) | R3: 3 Kg (nos) | S3: 1 Kg (nos) | T3: 2.5 kg (nos) | W3: Total
A4: Nashik | B4: 393 | C4: 0 | D4: 0 | E4: 0 | F4: 0 | G4: 0 | H4: 0 | I4: 0 | L4: Nashik | M4: 0 | N4: 19 | O4: 0 | P4: 0 | Q4: 0 | R4: 0 | S4: 0 | T4: 0 | W4: =SUM(M4:T4)/1000 -> 0.019
A5: Nalagarh | B5: 15 | C5: 81 | D5: 0 | E5: 0 | F5: 0 | G5: 0 | H5: 0 | I5: 0 | L5: Nalagarh | M5: 0 | N5: 23 | O5: 0 | P5: 0 | Q5: 0 | R5: 0 | S5: 0 | T5: 0 | W5: =SUM(M5:T5)/1000 -> 0.023
A6: Baddi | B6: 0 | C6: 150 | D6: 0 | E6: 0 | F6: 0 | G6: 0 | H6: 0 | I6: 0 | L6: Baddi | M6: 0 | N6: 102 | O6: 0 | P6: 0 | Q6: 0 | R6: 0 | S6: 0 | T6: 0 | W6: =SUM(M6:T6)/1000 -> 0.102
A7: Sikkim | B7: 0 | C7: 0 | D7: 0 | E7: 0 | F7: 0 | G7: 0 | H7: 0 | I7: 0 | L7: Sikkim | M7: 0 | N7: 3 | O7: 0 | P7: 0 | Q7: 0 | R7: 0 | S7: 0 | T7: 0 | W7: =SUM(M7:T7)/1000 -> 0.003
A8: Goa | B8: 48 | C8: =144+20 -> 164 | D8: 0 | E8: 0 | F8: 0 | G8: 0 | H8: 0 | I8: 0 | L8: Goa | M8: 6 | N8: 94 | O8: 0 | P8: 0 | Q8: 0 | R8: 0 | S8: 1 | T8: 0 | W8: =SUM(M8:T8)/1000 -> 0.101
A9: Indore | B9: 76 | C9: 0 | D9: 0 | E9: 0 | F9: 0 | G9: 0 | H9: 0 | I9: 0 | L9: Indore | M9: 0 | N9: 27 | O9: 0 | P9: 0 | Q9: 0 | R9: 8 | S9: 0 | T9: 0 | W9: =SUM(M9:T9)/1000 -> 0.035
A10: Aurangabad | B10: 14 | C10: 0 | D10: 0 | E10: 0 | F10: 20 | G10: 0 | H10: 0 | I10: 0 | L10: Aurangabad | M10: 5 | N10: 5 | O10: 12 | P10: 0 | Q10: 0 | R10: 0 | S10: 0 | T10: 0 | W10: =SUM(M10:T10)/1000 -> 0.022
W12: =SUM(M12:T12)/1000 -> 0
W13: =SUM(M13:T13)/1000 -> 0
W14: =SUM(M14:T14)/1000 -> 0
A15: Taloja | B15: 50 | C15: 0 | D15: 0 | E15: 0 | F15: 0 | G15: 0 | H15: 0 | I15: 8 | L15: Mohol | M15: 2 | N15: 4 | O15: 0 | P15: 0 | Q15: 0 | R15: 1 | S15: 0 | T15: 0 | W15: =SUM(M15:T15)/1000 -> 0.007
A16: Sinnar | B16: 0 | C16: 600 | D16: 0 | E16: 0 | F16: 0 | G16: 0 | H16: 0 | I16: 0 | L16: Taloja | M16: 0 | N16: 26 | O16: 0 | P16: 0 | Q16: 0 | R16: 1 | S16: 0 | T16: 0 | W16: =SUM(M16:T16)/1000 -> 0.027
A17: Emission factor (kg CO2) | B17: 1960 | C17: 1530 | D17: 1908 | E17: 4728 | F17: 2255 | G17: 2262 | H17: 79 | I17: 771 | L17: Sinnar | M17: 1 | N17: 22 | O17: 0 | P17: 0 | Q17: 1 | R17: 0 | S17: 0 | T17: 0 | W17: =SUM(M17:T17)/1000 -> 0.024
A18: Emissions tCO2 e | B18: =(SUM(B4:B16)*B17/1000) -> 1168.16 | C18: =(SUM(C4:C16)*C17/1000) -> 1522.35 | D18: =(SUM(D4:D16)*D17/1000) -> 0 | E18: =(SUM(E4:E16)*E17/1000) -> 0 | F18: =(SUM(F4:F16)*F17/1000) -> 45.1 | G18: =(SUM(G4:G16)*G17/1000) -> 0 | H18: =(SUM(H4:H16)*H17/1000) -> 0 | I18: =(SUM(I4:I16)*I17/1000) -> 6.168 | J18: Total Emissions tCO2e | K18: =SUM(B18:I18) -> 2741.778 | L18: Total | M18: =SUM(M4:M17) -> 14 | N18: =SUM(N4:N17) -> 325 | O18: =SUM(O4:O17) -> 12 | P18: =SUM(P4:P17) -> 0 | Q18: =SUM(Q4:Q17) -> 1 | R18: =SUM(R4:R17) -> 10 | S18: =SUM(S4:S17) -> 1 | T18: =SUM(T4:T17) -> 0
L19: Emissions tCO2 e | M19: =M18/1000 -> 0.014 | N19: =N18/1000 -> 0.325 | O19: =O18/1000 -> 0.012 | P19: =P18/1000 -> 0 | Q19: =Q18/1000 -> 0.001 | R19: =R18/1000 -> 0.01 | S19: =S18/1000 -> 0.001 | T19: =T18/1000 -> 0 | V19: =SUM(M19:T19) -> 0.363
A21: FY2020-21
A22: Plant | B22: R22 (kg) refilled | C22: R-134a (kg) refilled | D22: R-407c (kg) refilled | E22: R-404a (kg) refilled | F22: R-410a (kg) refilled | G22: R-407a (kg) refilled | H22: R123 (kg) refilled
A23: Nashik | B23: 184 | C23: 400 | D23: 9 | F23: 0
A24: Nalagarh | B24: 24.2 | C24: 11.7 | E24: 4.2
A25: Baddi | B25: 10
A26: Sikkim | B26: 4.8 | C26: 1.5 | D26: 3
A27: Goa | B27: 0.5 | C27: =284+318+238+1.68 -> 841.68 | D27: 1.68 | F27: =1.92+0.92 -> 2.84
A28: Indore | B28: 120
A29: Aurangabad | B29: 20 | C29: 40 | F29: 25
A34: Taloja | C34: 20 | H34: 3
A35: Sinnar | B35: 44.5 | C35: 1.9
A36: Emission factor (kg CO2) | B36: 1960 | C36: 1530 | D36: 1908 | E36: 4728 | F36: 2255 | G36: 2262 | H36: 79
A37: Emissions tCO2 e | B37: =(SUM(B23:B35)*B36/1000) -> 799.68 | C37: =(SUM(C23:C35)*C36/1000) -> 2014.6734 | D37: =(SUM(D23:D35)*D36/1000) -> 26.10144 | E37: =(SUM(E23:E35)*E36/1000) -> 19.8576 | F37: =(SUM(F23:F35)*F36/1000) -> 62.7792 | G37: =(SUM(G23:G35)*G36/1000) -> 0 | H37: =(SUM(H23:H35)*H36/1000) -> 0.237 | J37: Total Emissions tCO2e | K37: =SUM(B37:H37) -> 2923.3286
A40: FY2022-23 | L40: CO2 Type fire extinguisher refilled in nos
A41: Plant | B41: R22 (kg) refilled | C41: R-134a (kg) refilled | D41: R-407c (kg) refilled | E41: R-404a (kg) refilled | F41: R-410a (kg) refilled | G41: R-407a (kg) refilled | H41: R123 (kg) refilled | I41: R32 (kg) refilled | L41: Plant | M41: 2 Kg (nos) | N41: 4.5 Kg (nos) | O41: 9 Kg (nos) | P41: 22.5 Kg (nos) | Q41: 6 Kg (nos) | R41: 3 Kg (nos) | S41: 1 Kg (nos) | T41: 2.5 kg (nos) | V41: Total
A42: Nashik | B42: 178 | C42: 4.5 | D42: 0 | E42: 0 | F42: 2 | G42: 0 | H42: 0 | I42: 0 | L42: Nashik | M42: 4 | N42: 10 | O42: 0 | P42: 0 | Q42: 0 | R42: 0 | S42: 0 | T42: 0
A43: Nalagarh | B43: 12 | C43: 0 | D43: 0 | E43: 3 | F43: 0 | G43: 0 | H43: 0 | I43: 0 | L43: Nalagarh | M43: 0 | N43: 9 | O43: 0 | P43: 0 | Q43: 0 | R43: 0 | S43: 0 | T43: 0
A44: Baddi | B44: 9 | C44: 0 | D44: 0 | E44: 0 | F44: 0 | G44: 0 | H44: 0 | I44: 0 | L44: Baddi | M44: 0 | N44: 30 | O44: 0 | P44: 0 | Q44: 0 | R44: 0 | S44: 0 | T44: 0
A45: Sikkim | B45: 0 | C45: 80 | D45: 0 | E45: 0 | F45: 0 | G45: 0 | H45: 0 | I45: 0 | L45: Sikkim | M45: 2 | N45: 4 | O45: 0 | P45: 0 | Q45: 0 | R45: 2 | S45: 0 | T45: 0
A46: Goa | B46: =158+55 -> 213 | C46: 81 | D46: 0 | E46: 0 | F46: 0 | G46: 0 | H46: 0 | I46: 0 | L46: Goa | M46: 12 | N46: 144 | O46: 0 | P46: 0 | Q46: 0 | R46: 0 | S46: 5 | T46: 0
A47: Indore | B47: 122 | C47: 0 | D47: 0 | E47: 0 | F47: 0 | G47: 0 | H47: 0 | I47: 0 | L47: Indore | M47: 0 | N47: 64 | O47: 13 | P47: 0 | Q47: 0 | R47: 0 | S47: 0 | T47: 0
A48: Aurangabad | B48: 22 | C48: 0 | D48: 9 | E48: 0 | F48: 38 | G48: 0 | H48: 0 | I48: 0 | L48: Aurangabad | M48: 4 | N48: 3 | O48: 4 | P48: 1 | Q48: 0 | R48: 0 | S48: 0 | T48: 0
...

Sheet Electricity
A2: Scope 2 - Purchased electricity & Renewables
B3: 2021-22 | E3: 2020-21
A4: Kwh | B4: NRE | C4: RE | E4: NRE | F4: RE
A5: Baddi | B5: 10910892 | E5: 9835027 | H5: =B5*0.79/1000 -> 8619.6047
A6: Goa S7 | B6: 26671050 | E6: 29022210 | H6: =B6*0.79/1000 -> 21070.129
A7: Goa S9 | B7: 6095370 | E7: 5958670 | H7: =B7*0.79/1000 -> 4815.3423
A8: Indore | B8: 21044790 | E8: 20713356 | H8: =B8*0.79/1000 -> 16625.384 | K8: 9.31 | L8: 9.59
A9: Nashik | B9: 3993830 | E9: 4486828 | H9: =B9*0.79/1000 -> 3155.1257 | L9: =(K8-L8)/L8 -> -0.02919708
A10: Nalagarh | B10: 2014380 | E10: 2193460 | H10: =B10*0.79/1000 -> 1591.3602
A11: Sikkim | B11: 2536370 | E11: 2462690 | H11: =B11*0.79/1000 -> 2003.7323 | K11: Open Access | L11: Rooftop
K12: =C12 -> 0 | L12: 0
A13: Aurangabad | B13: 7608723 | E13: 6363429 | H13: =B13*0.79/1000 -> 6010.8912
K16: 0 | L16: =C16 -> 0
A17: Mahape | B17: 1503870 | C17: 3159991 | D17: =C17/(B17+C17) -> 0.67754828 | E17: 1034165 | F17: 3380933 | G17: =F17/(E17+F17) -> 0.76576624 | H17: =B17*0.79/1000 -> 1188.0573 | K17: 3083402 | L17: 76589
A18: Sinnar | B18: 725935 | E18: 723149 | H18: =B18*0.79/1000 -> 573.48865
A19: Taloja | B19: 1348094 | C19: 2641346 | D19: =C19/(B19+C19) -> 0.6620844 | E19: 1109229 | F19: 2198161 | G19: =F19/(E19+F19) -> 0.66462105 | H19: =B19*0.79/1000 -> 1064.9943 | K19: =C19 -> 2641346
A20: Sanpada | B20: 26224 | E20: 293908 | H20: =B20*0.79/1000 -> 20.71696 | K20: =SUM(K12:K19) -> 5724748 | L20: =SUM(L12:L19) -> 76589 | M20: =L20*0.00079 -> 60.50531
A21: Total | B21: =SUM(B5:B20) -> 84479528 | C21: =SUM(C5:C20) -> 5801337 | E21: =SUM(E5:E20) -> 84196121 | F21: =SUM(F5:F20) -> 5579094 | H21: =(C21-F21)/F21 -> 0.039834962 | K21: =K20/1000000 -> 5.724748 | L21: =L20/1000000 -> 0.076589 | M21: =K21+L21 -> 5.801337
A22: Energy GJ | B22: =0.0036*B21 -> 304126.3 | C22: =0.0036*C21 -> 20884.813 | E22: =0.0036*E21 -> 303106.04 | F22: =0.0036*F21 -> 20084.738 | H22: =(C22-F22)/F22 -> 0.039834962
A23: Emissions in TCO2 | B23: =(0.79/1000)*B21 -> 66738.827 | E23: =E21*0.00079 -> 66514.936 | H23: =SUM(H5:H20) -> 66738.827
B25: =C21/(B21+C21) -> 0.064258766
A26: Energy Renewable (GJ) F22 | B26: =C22 -> 20884.813 | C26: =SUM(B21:C21)/1000000 -> 90.280865 | H26: =(C21-F21)/F21 -> 0.039834962
A27: Energy Renewable (GJ) F21 | B27: =F22 -> 20084.738
A29: Energy Non Renewable (GJ) F22 | B29: =B22 -> 304126.3
A30: Energy Non Renewable (GJ) F21 | B30: =E22 -> 303106.04
A35: Scope 2 - Purchased electricity & Renewables | F35: Scope 2 - Purchased electricity & Renewables
B36: 2022-23 | G36: 2023-24 | N36: 2024-25
A37: Kwh | B37: NRE | C37: RE | F37: Kwh | G37: NRE | H37: RE | M37: Kwh | N37: NRE | O37: RE
A38: Baddi | B38: 12607258 | F38: Baddi | G38: 13977304 | M38: Baddi | N38: 16456608
A39: Goa S7 | B39: 27398430 | F39: Goa S7 | G39: 29121300 | M39: Goa S7 | N39: 30656520
A40: Goa S9 | B40: 6459750 | F40: Goa S9 | G40: 6914250 | M40: Goa S9 | N40: 7035660
A41: Indore | B41: 21977766 | F41: Indore | G41: 23610826 | M41: Indore | N41: 23624090
A42: Nashik | B42: 3973078 | F42: Nashik | G42: 3957440 | M42: Nashik | N42: 4001814
A43: Nalagarh | B43: 2229650 | F43: Nalagarh | G43: 2049980 | M43: Nalagarh | N43: 2113140
A44: Sikkim | B44: 2641600 | F44: Sikkim | G44: 2596322 | M44: Sikkim | N44: 2502237
A46: Aurangabad | B46: 9381135 | F46: Aurangabad | G46: 10183350 | M46: Aurangabad | N46: 13337195
P49: RE %
A50: Mahape | B50: 1628589 | C50: 3486120 | D50: =C50/(B50+C50) -> 0.68158716 | F50: Mahape | G50: 1873615 | H50: 2875932 | I50: =H50/(G50+H50) -> 0.60551712 | M50: Mahape | N50: 1942516 | O50: 2691178 | P50: =O50/(N50+O50) -> 0.58078457
A51: Sinnar | B51: 724204 | F51: Sinnar | G51: 702295 | M51: Sinnar | N51: 777287
A52: Taloja | B52: 2134571 | C52: 2300003 | D52: =C52/(B52+C52) -> 0.51865252 | F52: Taloja | G52: 2250693 | H52: 2257616 | I52: =H52/(G52+H52) -> 0.5007678 | M52: Taloja | N52: 2348003 | O52: 1920510 | P52: =O52/(N52+O52) -> 0.44992483
...
